<?xml version="1.0"?>

<robot name="my_robot">
	<material name="blue">
  		<color rgba="0 0 0.8 1"/>
	</material>

	<material name="white">
  		<color rgba="1 1 1 1"/>
	</material>

	<material name="red">
  		<color rgba="1 0 0 1"/>
	</material>

	<link name="base_footprint">
	  <visual>
		<origin rpy="0 0 0" xyz="0 0 0"/>
		<geometry>
		  <box size="0.001 0.001 0.001"/>
		</geometry>
	  </visual>
	</link>

	<gazebo reference="base_footprint">
	  <turnGravityOff>false</turnGravityOff>
	</gazebo>

	<joint name="base_footprint_joint" type="fixed">
	  <origin rpy="0 0 0" xyz="0 0 0.2"/>
	  <parent link="base_footprint"/>
	  <child link="base_link"/>
	</joint>

	<link name="base_link">
      <inertial>
        <mass value="3"/>
        <origin xyz="0 0 0"/>
        <inertia ixx="0.0282916666667" ixy="0" ixz="0" iyy="0.0282916666667" iyz="0" izz="0.05625"/>
      </inertial>
      <visual>
        <origin rpy="0 0 0" xyz="0 0 0"/>
        <geometry>
          <cylinder length="0.05" radius="0.75"/>
        </geometry>
        <material name="white"/>
      </visual>
      <collision>
        <origin rpy="0 0 0 " xyz="0 0 0"/>
        <geometry>
          <cylinder length="0.05" radius="0.75"/>
        </geometry>
      </collision>
    </link>

	<gazebo reference="base_link">
      <turnGravityOff>false</turnGravityOff>
    </gazebo>

	<link name="right_wheel">
        <visual>
			<origin rpy="1.57079632679 0 0" xyz="0 0 0"/>
            <geometry>
                <cylinder length="0.1" radius="0.2"/>
            </geometry>
			<material name="blue"/>
        </visual>
		<collision>
		  <origin rpy="1.57079632679 0 0 " xyz="0 0 0"/>
		  <geometry>
		    <cylinder length="0.1" radius="0.2"/>
		  </geometry>
		</collision>
		<inertial>
		  <mass value="1"/>
		  <inertia ixx="1.0" ixy="0.0" ixz="0.0" iyy="1.0" iyz="0.0" izz="1.0"/>
		</inertial>
    </link>

	<gazebo reference="right_wheel">
		<mu1 value="200.0"/>
  		<mu2 value="100.0"/>
  		<kp value="10000000.0" />
  		<kd value="1.0" />
  		<material>Gazebo/Grey</material>
      <turnGravityOff>false</turnGravityOff>
    </gazebo>

	<joint name="right_wheel_joint" type="continuous">
      <parent link="base_link"/>
      <child link="right_wheel"/>
      <origin rpy="0 0 0" xyz="0.0 0.75 0.0"/>
      <axis rpy="0  0" xyz="0 1 0"/>
      <limit effort="100" velocity="100"/>
      <joint_properties damping="0.0" friction="0.0"/>
    </joint>

	<transmission name="right_wheel_control">
  		<type>transmission_interface/SimpleTransmission</type>
  		<actuator name="right_wheel_motor">
			<mechanicalReduction>1</mechanicalReduction>
  		</actuator>
  		<joint name="right_wheel_joint">
			<hardwareInterface>hardware_interface/EffortJointInterface</hardwareInterface>
  		</joint>
	</transmission>

	<link name="left_wheel">
        <visual>
			<origin rpy="1.57079632679 0 0" xyz="0 0 0"/>
            <geometry>
                <cylinder length="0.1" radius="0.2"/>
            </geometry>
			<material name="blue"/>
        </visual>
		<collision>
		  <origin rpy="1.57079632679 0 0" xyz="0 0 0"/>
		  <geometry>
		    <cylinder length="0.1" radius="0.2"/>
		  </geometry>
		</collision>
		<inertial>
		  <mass value="1"/>
		  <inertia ixx="1.0" ixy="0.0" ixz="0.0" iyy="1.0" iyz="0.0" izz="1.0"/>
		</inertial>
    </link>

	<gazebo reference="left_wheel">
		<mu1 value="200.0"/>
    	<mu2 value="100.0"/>
    	<kp value="10000000.0" />
    	<kd value="1.0" />
    	<material>Gazebo/Grey</material>
        <turnGravityOff>false</turnGravityOff>
    </gazebo>

	<joint name="left_wheel_joint" type="continuous">
	    <parent link="base_link"/>
	    <child link="left_wheel"/>
	    <origin rpy="0 0 0" xyz="0.0 -0.75 0.0"/>
	    <axis rpy="0  0" xyz="0 1 0"/>
	    <limit effort="100" velocity="100"/>
	    <joint_properties damping="0.0" friction="0.0"/>
	  </joint>

	<transmission name="left_wheel_control">
		<type>transmission_interface/SimpleTransmission</type>
		<actuator name="left_wheel_motor">
			<mechanicalReduction>1</mechanicalReduction>
		</actuator>
		<joint name="left_wheel_joint">
			<hardwareInterface>hardware_interface/EffortJointInterface</hardwareInterface>
		</joint>
	</transmission>

	<gazebo>
	  <plugin filename="libgazebo_ros_diff_drive.so" name="differential_drive_controller_front">
		<rosDebugLevel>Debug</rosDebugLevel>
		<publishWheelTF>false</publishWheelTF>
		<robotNamespace>/</robotNamespace>
		<publishTf>1</publishTf>
		<publishWheelJointState>false</publishWheelJointState>
		<alwaysOn>true</alwaysOn>
		<updateRate>100.0</updateRate>
		<legacyMode>true</legacyMode>
		<leftJoint>left_wheel_joint</leftJoint>
		<rightJoint>right_wheel_joint</rightJoint>
		<wheelSeparation>1.5</wheelSeparation>
		<wheelDiameter>0.4</wheelDiameter>
		<broadcastTF>1</broadcastTF>
		<wheelTorque>30</wheelTorque>
		<wheelAcceleration>1.8</wheelAcceleration>
		<commandTopic>cmd_vel</commandTopic>
		<odometryFrame>odom</odometryFrame>
		<odometryTopic>odom</odometryTopic>
		<odometrySource>world</odometrySource>
		<publishOdomTF>true</publishOdomTF>
		<robotBaseFrame>base_footprint</robotBaseFrame>
	  </plugin>
	</gazebo>

<!-- ============================= SENSORS ========================================= -->
	<link name="hokuyo_link">
        <visual>
			<origin rpy="0 0 0" xyz="0 0 0"/>
            <geometry>
                <box size="0.1 0.1 0.1"/>
            </geometry>
			<material name="blue"/>
        </visual>
    </link>

	<joint name="hokuyo_joint" type="fixed">
		<parent link="base_link"/>
		<child link="hokuyo_link"/>
		<origin xyz="0.70 0 0.075" rpy="0 0 0" />
	</joint>

	<gazebo reference="hokuyo_link">
    <material>Gazebo/Blue</material>
	    <sensor name="head_hokuyo_sensor" type="ray">
	      <pose>0.05 0 0 0 0 0</pose>
	      <visualize>true</visualize>
	      <update_rate>40</update_rate>
	      <ray>
	        <scan>
	          <horizontal>
	            <samples>720</samples>
	            <resolution>1</resolution>
	            <min_angle>-1.570796</min_angle>
	            <max_angle>1.570796</max_angle>
	          </horizontal>
	        </scan>
	        <range>
	          <min>0.10</min>
	          <max>10.0</max>
	          <resolution>0.001</resolution>
	        </range>
	      </ray>
	      <plugin filename="libgazebo_ros_laser.so" name="gazebo_ros_head_hokuyo_controller">
	        <topicName>/scan</topicName>
	        <frameName>hokuyo_link</frameName>
	      </plugin>
	    </sensor>
  	</gazebo>

    <!--       3D sensor          -->
    <!--http://answers.gazebosim.org/question/4266/gazebo-15-libgazebo_openni_kinectso-pointcloud-data-is-rotated-and-flipped/ -->
    <!--https://answers.ros.org/question/232534/gazebo-camera-frame-is-inconsistent-with-rviz-opencv-convention/?answer=232562#post-id-232562-->
    <link name="depth_image_link">
      <inertial>
        <!-- <pose>-0.069 0 0.104 0 0 0</pose>-->
        <origin xyz="0 0 0" rpy="0 0 0"/>
        <inertia ixx="1.0" ixy="0.0" ixz="0.0" iyy="1.0" iyz="0.0" izz="1.0"/>
        <mass value="0.035"/>
      </inertial>
      <visual>
        <origin xyz="0 0 0" rpy="0 0 0"/>
        <geometry>
            <box size="0.008 0.130 0.022"/>
        </geometry>
        <material name="red"/>
      </visual>

      <collision name="depth_image_collision">
        <!-- <pose>-0.069 0 0.104 0 0 0</pose>-->
        <geometry>
          <box size="0.008 0.130 0.022"/>
        </geometry>
      </collision>
    </link>

    <joint name="image_joint" type="fixed">
      <parent link="base_link"/>
      <child link="depth_image_link"/>
      <origin xyz="0.70 0 0.175" rpy="0 0 0" />
      <!--<pose>0.1 0 0.1 0 0 0</pose>-->
    </joint>
    <!--https://www.ros.org/reps/rep-0103.html#suffix-frames -->
    <joint name="camera_optical_joint" type="fixed">
        <!-- these values have to be these values otherwise the gazebo camera
            image won't be aligned properly with the frame it is supposedly
            originating from -->
        <origin xyz="0 0 0" rpy="-1.570796326 0 -1.570796326"/>
        <parent link="depth_image_link"/>
        <child link="camera_link_optical"/>
    </joint>

    <link name="camera_link_optical">
    </link>

    <gazebo reference="depth_image_link">
    <material>Gazebo/Red</material>
    <sensor name="depth_image_camera" type="depth">
        <update_rate>20</update_rate>
        <visualize>true</visualize>
        <camera>
            <horizontal_fov>1.3962634</horizontal_fov> <!-- 1.047198 1.3962634 -->
            <image>
                <width>640</width>
                <height>480</height>
                <format>R8G8B8</format>
            </image>
            <clip>
                <near>0.005</near>
                <far>30</far>
            </clip>
        </camera>
        <plugin name="depth_image_controller" filename="libgazebo_ros_openni_kinect.so">
            <baseline>0.2</baseline>
            <alwaysOn>true</alwaysOn>
            <updateRate>0.0</updateRate>
            <cameraName>depth_camera_ir</cameraName>
            <imageTopicName>/depth_camera/image/image_raw</imageTopicName>
            <cameraInfoTopicName>/depth_camera/image/camera_info</cameraInfoTopicName>
            <depthImageTopicName>/depth_camera/depth/image_raw</depthImageTopicName>
            <depthImageInfoTopicName>/depth_camera/depth/camera_info</depthImageInfoTopicName>
            <pointCloudTopicName>/depth_camera/depth/points</pointCloudTopicName>
            <frameName>camera_link_optical</frameName>
            <pointCloudCutoff>0.4</pointCloudCutoff>
            <pointCloudCutoffMax>3.0</pointCloudCutoffMax>
            <distortionK1>0.00000001</distortionK1>
            <distortionK2>0.00000001</distortionK2>
            <distortionK3>0.00000001</distortionK3>
            <distortionT1>0.00000001</distortionT1>
            <distortionT2>0.00000001</distortionT2>
            <CxPrime>0</CxPrime>
            <Cx>0</Cx>
            <Cy>0</Cy>
            <focalLength>0</focalLength>
            <hackBaseline>0.07</hackBaseline>
        </plugin>
    </sensor>
    </gazebo>

<!-- ====================================CASTER WHEELS========================================== -->

	<link name="caster_wheel_back">
		<visual>
			<origin rpy="0 0 0" xyz="0 0 -0.1"/>
			<geometry>
                <sphere radius="0.1"/>
            </geometry>
		</visual>
		<collision>
			<origin rpy="0 0 0" xyz="0 0 -0.1"/>
			<geometry>
                <sphere radius="0.1"/>
            </geometry>
		</collision>
		<inertial>
			<origin xyz="0 0 0" />
			<mass value="1"/>
			<inertia ixx="1.0" ixy="0.0" ixz="0.0" iyy="1.0" iyz="0.0" izz="1.0"/>
		</inertial>
	</link>

	<joint name="base_to_caster_back" type="fixed">
		<parent link="base_link"/>
		<child link="caster_wheel_back"/>
		<origin rpy="0 0 0" xyz="-0.650 0 0" />
	</joint>

	<gazebo reference="caster_wheel_back">
		<mu1 value="0.0"/>
		<mu2 value="0.0"/>
		<turnGravityOff>false</turnGravityOff>
		<material>Gazebo/Grey</material>
	</gazebo>

	<link name="caster_wheel_front">
		<visual>
			<origin rpy="0 0 0" xyz="0 0 -0.1"/>
			<geometry>
				<sphere radius="0.1"/>
			</geometry>
		</visual>
		<collision>
			<origin rpy="0 0 0" xyz="0 0 -0.1"/>
			<geometry>
				<sphere radius="0.1"/>
			</geometry>
		</collision>
		<inertial>
			<origin xyz="0 0 0" />
			<mass value="1"/>
			<inertia ixx="1.0" ixy="0.0" ixz="0.0" iyy="1.0" iyz="0.0" izz="1.0"/>
		</inertial>
	</link>

	<joint name="base_to_caster_front" type="fixed">
		<parent link="base_link"/>
		<child link="caster_wheel_front"/>
		<origin rpy="0 0 0" xyz="0.650 0 0" />
	</joint>

	<gazebo reference="caster_wheel_front">
		<mu1 value="0.0"/>
		<mu2 value="0.0"/>
		<turnGravityOff>false</turnGravityOff>
		<material>Gazebo/Grey</material>
	</gazebo>

	<gazebo>
	    <plugin name="gazebo_ros_control" filename="libgazebo_ros_control.so">
	      <robotNamespace>/</robotNamespace>
	    </plugin>
  	</gazebo>

</robot>
